Workbook

Sheet Overview
B2: Case 01 — AP Invoice Cycle-Time Analysis
B4: Supports the Process Improvement Charter. Brightpath Distribution's AP invoice approval process is flat: every invoice $500+ requires the same three sequential approvals regardless of size. This workbook measures the current-state cost of that in one month of observed data, then models a tiered, tool-assisted future state.
B6: Color legend
B7: Blue text | C7: Hardcoded input / assumption you can change
B8: Yellow fill | C8: Key assumption — worth double-checking before relying on the output
B9: Black text | C9: Formula — recalculates automatically
B10: Green text | C10: Link pulled from another sheet
B12: Sheets
B13: • Invoice Sample — 120 observed invoices from one month, current-state process
B14: • Bottleneck Analysis — where the time actually goes, by stage and by tier
B15: • Future-State Model — tiered approvals + routing tool, projected row by row
B16: • Summary — headline before/after KPIs

Sheet Invoice Sample
A1: Invoice ID | B1: Vendor | C1: Vendor Type | D1: Department | E1: Amount | F1: Payment Terms | G1: Days: Data Entry | H1: Days: Dept Mgr Approval | I1: Days: Finance Mgr Approval | J1: Days: Controller Approval | K1: Days: Payment Processing | L1: Total Cycle Days | M1: Tier | N1: Discount Eligible? | O1: Discount Captured? | P1: Late Fee Incurred? | Q1: Discount $ Missed | R1: Late Fee $ Incurred
A2: INV-2031 | B2: Cascade Freight Partners | C2: Recurring | D2: Sales & Marketing | E2: 13377.69 | F2: Net 30 | G2: 1.3 | H2: 6.3 | I2: 5.1 | J2: 4.6 | K2: 1.4 | L2: =SUM(G2:K2) -> 18.7 | M2: =IF(E2<500,"Tier 0 (<$500)",IF(E2<10000,"Tier 1 ($500-$10K)",IF(E2<50000,"Tier 2 ($10K-$50K)","Tier 3 (>$50K)"))) -> Tier 2 ($10K-$50K) | N2: =IF(F2="2/10 Net 30","Yes","No") -> No | O2: =IF(AND(N2="Yes",(G2+H2+I2+J2)<=10),"Yes","No") -> No | P2: =IF(L2>30,"Yes","No") -> No | Q2: =IF(AND(N2="Yes",O2="No"),E2*0.02,0) -> 0 | R2: =IF(P2="Yes",E2*0.015,0) -> 0
A3: INV-2032 | B3: Meridian Cleaning Supply | C3: Recurring | D3: Fleet & Logistics | E3: 9287.72 | F3: Net 30 | G3: 0.7 | H3: 5.1 | I3: 3.5 | J3: 1.6 | K3: 0.7 | L3: =SUM(G3:K3) -> 11.6 | M3: =IF(E3<500,"Tier 0 (<$500)",IF(E3<10000,"Tier 1 ($500-$10K)",IF(E3<50000,"Tier 2 ($10K-$50K)","Tier 3 (>$50K)"))) -> Tier 1 ($500-$10K) | N3: =IF(F3="2/10 Net 30","Yes","No") -> No | O3: =IF(AND(N3="Yes",(G3+H3+I3+J3)<=10),"Yes","No") -> No | P3: =IF(L3>30,"Yes","No") -> No | Q3: =IF(AND(N3="Yes",O3="No"),E3*0.02,0) -> 0 | R3: =IF(P3="Yes",E3*0.015,0) -> 0
A4: INV-2033 | B4: Blackstone Facility Repair | C4: One-off | D4: Warehouse Ops | E4: 29465.85 | F4: Net 30 | G4: 1.7 | H4: 2.5 | I4: 0.6 | J4: 4.4 | K4: 0.8 | L4: =SUM(G4:K4) -> 10 | M4: =IF(E4<500,"Tier 0 (<$500)",IF(E4<10000,"Tier 1 ($500-$10K)",IF(E4<50000,"Tier 2 ($10K-$50K)","Tier 3 (>$50K)"))) -> Tier 2 ($10K-$50K) | N4: =IF(F4="2/10 Net 30","Yes","No") -> No | O4: =IF(AND(N4="Yes",(G4+H4+I4+J4)<=10),"Yes","No") -> No | P4: =IF(L4>30,"Yes","No") -> No | Q4: =IF(AND(N4="Yes",O4="No"),E4*0.02,0) -> 0 | R4: =IF(P4="Yes",E4*0.015,0) -> 0
A5: INV-2034 | B5: Norwood Uniform Services | C5: Recurring | D5: Facilities | E5: 705.29 | F5: Net 30 | G5: 1.3 | H5: 3.8 | I5: 2.2 | J5: 1.3 | K5: 0.9 | L5: =SUM(G5:K5) -> 9.5 | M5: =IF(E5<500,"Tier 0 (<$500)",IF(E5<10000,"Tier 1 ($500-$10K)",IF(E5<50000,"Tier 2 ($10K-$50K)","Tier 3 (>$50K)"))) -> Tier 1 ($500-$10K) | N5: =IF(F5="2/10 Net 30","Yes","No") -> No | O5: =IF(AND(N5="Yes",(G5+H5+I5+J5)<=10),"Yes","No") -> No | P5: =IF(L5>30,"Yes","No") -> No | Q5: =IF(AND(N5="Yes",O5="No"),E5*0.02,0) -> 0 | R5: =IF(P5="Yes",E5*0.015,0) -> 0
A6: INV-2035 | B6: Delmar Industrial Supply | C6: Recurring | D6: Sales & Marketing | E6: 384.61 | F6: Net 30 | G6: 1.5 | H6: 3.3 | I6: 0 | J6: 0 | K6: 0.6 | L6: =SUM(G6:K6) -> 5.4 | M6: =IF(E6<500,"Tier 0 (<$500)",IF(E6<10000,"Tier 1 ($500-$10K)",IF(E6<50000,"Tier 2 ($10K-$50K)","Tier 3 (>$50K)"))) -> Tier 0 (<$500) | N6: =IF(F6="2/10 Net 30","Yes","No") -> No | O6: =IF(AND(N6="Yes",(G6+H6+I6+J6)<=10),"Yes","No") -> No | P6: =IF(L6>30,"Yes","No") -> No | Q6: =IF(AND(N6="Yes",O6="No"),E6*0.02,0) -> 0 | R6: =IF(P6="Yes",E6*0.015,0) -> 0
A7: INV-2036 | B7: Cascade Freight Partners | C7: Recurring | D7: Sales & Marketing | E7: 75964.56 | F7: Net 30 | G7: 1.5 | H7: 2.7 | I7: 5.2 | J7: 4.6 | K7: 1 | L7: =SUM(G7:K7) -> 15 | M7: =IF(E7<500,"Tier 0 (<$500)",IF(E7<10000,"Tier 1 ($500-$10K)",IF(E7<50000,"Tier 2 ($10K-$50K)","Tier 3 (>$50K)"))) -> Tier 3 (>$50K) | N7: =IF(F7="2/10 Net 30","Yes","No") -> No | O7: =IF(AND(N7="Yes",(G7+H7+I7+J7)<=10),"Yes","No") -> No | P7: =IF(L7>30,"Yes","No") -> No | Q7: =IF(AND(N7="Yes",O7="No"),E7*0.02,0) -> 0 | R7: =IF(P7="Yes",E7*0.015,0) -> 0
A8: INV-2037 | B8: Overton Safety Gear | C8: Recurring | D8: Finance | E8: 16584.15 | F8: 2/10 Net 30 | G8: 0.8 | H8: 2.1 | I8: 4.1 | J8: 6.5 | K8: 1 | L8: =SUM(G8:K8) -> 14.5 | M8: =IF(E8<500,"Tier 0 (<$500)",IF(E8<10000,"Tier 1 ($500-$10K)",IF(E8<50000,"Tier 2 ($10K-$50K)","Tier 3 (>$50K)"))) -> Tier 2 ($10K-$50K) | N8: =IF(F8="2/10 Net 30","Yes","No") -> Yes | O8: =IF(AND(N8="Yes",(G8+H8+I8+J8)<=10),"Yes","No") -> No | P8: =IF(L8>30,"Yes","No") -> No | Q8: =IF(AND(N8="Yes",O8="No"),E8*0.02,0) -> 331.683 | R8: =IF(P8="Yes",E8*0.015,0) -> 0
A9: INV-2038 | B9: Blackstone Facility Repair | C9: One-off | D9: Sales & Marketing | E9: 22636.85 | F9: Net 30 | G9: 1.5 | H9: 5.9 | I9: 4.4 | J9: 6.5 | K9: 1.1 | L9: =SUM(G9:K9) -> 19.4 | M9: =IF(E9<500,"Tier 0 (<$500)",IF(E9<10000,"Tier 1 ($500-$10K)",IF(E9<50000,"Tier 2 ($10K-$50K)","Tier 3 (>$50K)"))) -> Tier 2 ($10K-$50K) | N9: =IF(F9="2/10 Net 30","Yes","No") -> No | O9: =IF(AND(N9="Yes",(G9+H9+I9+J9)<=10),"Yes","No") -> No | P9: =IF(L9>30,"Yes","No") -> No | Q9: =IF(AND(N9="Yes",O9="No"),E9*0.02,0) -> 0 | R9: =IF(P9="Yes",E9*0.015,0) -> 0
A10: INV-2039 | B10: Juniper Equipment Rental | C10: One-off | D10: Fleet & Logistics | E10: 131.44 | F10: Net 30 | G10: 1.5 | H10: 3.5 | I10: 0 | J10: 0 | K10: 1.4 | L10: =SUM(G10:K10) -> 6.4 | M10: =IF(E10<500,"Tier 0 (<$500)",IF(E10<10000,"Tier 1 ($500-$10K)",IF(E10<50000,"Tier 2 ($10K-$50K)","Tier 3 (>$50K)"))) -> Tier 0 (<$500) | N10: =IF(F10="2/10 Net 30","Yes","No") -> No | O10: =IF(AND(N10="Yes",(G10+H10+I10+J10)<=10),"Yes","No") -> No | P10: =IF(L10>30,"Yes","No") -> No | Q10: =IF(AND(N10="Yes",O10="No"),E10*0.02,0) -> 0 | R10: =IF(P10="Yes",E10*0.015,0) -> 0
A11: INV-2040 | B11: Blackstone Facility Repair | C11: One-off | D11: Fleet & Logistics | E11: 3447.76 | F11: Net 30 | G11: 1.5 | H11: 4.1 | I11: 3.6 | J11: 4.5 | K11: 1.4 | L11: =SUM(G11:K11) -> 15.1 | M11: =IF(E11<500,"Tier 0 (<$500)",IF(E11<10000,"Tier 1 ($500-$10K)",IF(E11<50000,"Tier 2 ($10K-$50K)","Tier 3 (>$50K)"))) -> Tier 1 ($500-$10K) | N11: =IF(F11="2/10 Net 30","Yes","No") -> No | O11: =IF(AND(N11="Yes",(G11+H11+I11+J11)<=10),"Yes","No") -> No | P11: =IF(L11>30,"Yes","No") -> No | Q11: =IF(AND(N11="Yes",O11="No"),E11*0.02,0) -> 0 | R11: =IF(P11="Yes",E11*0.015,0) -> 0
A12: INV-2041 | B12: Ashford Packaging Co. | C12: Recurring | D12: IT | E12: 1657.29 | F12: Net 30 | G12: 0.9 | H12: 2.1 | I12: 2.5 | J12: 3.5 | K12: 1.3 | L12: =SUM(G12:K12) -> 10.3 | M12: =IF(E12<500,"Tier 0 (<$500)",IF(E12<10000,"Tier 1 ($500-$10K)",IF(E12<50000,"Tier 2 ($10K-$50K)","Tier 3 (>$50K)"))) -> Tier 1 ($500-$10K) | N12: =IF(F12="2/10 Net 30","Yes","No") -> No | O12: =IF(AND(N12="Yes",(G12+H12+I12+J12)<=10),"Yes","No") -> No | P12: =IF(L12>30,"Yes","No") -> No | Q12: =IF(AND(N12="Yes",O12="No"),E12*0.02,0) -> 0 | R12: =IF(P12="Yes",E12*0.015,0) -> 0
A13: INV-2042 | B13: Meridian Cleaning Supply | C13: Recurring | D13: Warehouse Ops | E13: 14950.03 | F13: Net 30 | G13: 1 | H13: 3.6 | I13: 5.3 | J13: 4.9 | K13: 1.4 | L13: =SUM(G13:K13) -> 16.2 | M13: =IF(E13<500,"Tier 0 (<$500)",IF(E13<10000,"Tier 1 ($500-$10K)",IF(E13<50000,"Tier 2 ($10K-$50K)","Tier 3 (>$50K)"))) -> Tier 2 ($10K-$50K) | N13: =IF(F13="2/10 Net 30","Yes","No") -> No | O13: =IF(AND(N13="Yes",(G13+H13+I13+J13)<=10),"Yes","No") -> No | P13: =IF(L13>30,"Yes","No") -> No | Q13: =IF(AND(N13="Yes",O13="No"),E13*0.02,0) -> 0 | R13: =IF(P13="Yes",E13*0.015,0) -> 0
... A121: INV-2150 | B121: Harlow Fasteners Inc. | C121: Recurring | D121: Sales & Marketing | E121: 8318.89 | F121: 2/10 Net 30 | G121: 1.1 | H121: 0.7 | I121: 2.5 | J121: 3.6 | K121: 0.8 | L121: =SUM(G121:K121) -> 8.7 | M121: =IF(E121<500,"Tier 0 (<$500)",IF(E121<10000,"Tier 1 ($500-$10K)",IF(E121<50000,"Tier 2 ($10K-$50K)","Tier 3 (>$50K)"))) -> Tier 1 ($500-$10K) | N121: =IF(F121="2/10 Net 30","Yes","No") -> Yes | O121: =IF(AND(N121="Yes",(G121+H121+I121+J121)<=10),"Yes","No") -> Yes | P121: =IF(L121>30,"Yes","No") -> No | Q121: =IF(AND(N121="Yes",O121="No"),E121*0.02,0) -> 0 | R121: =IF(P121="Yes",E121*0.015,0) -> 0

Sheet Bottleneck Analysis
B2: Bottleneck Analysis — current state
B4: Average days by stage (all invoices unless noted)
B5: Data entry — recurring vendors | E5: =AVERAGEIFS('Invoice Sample'!G2:G121,'Invoice Sample'!C2:C121,"Recurring") -> 1.1872093
B6: Data entry — one-off vendors | E6: =AVERAGEIFS('Invoice Sample'!G2:G121,'Invoice Sample'!C2:C121,"One-off") -> 1.5735294
B7: Dept Mgr approval (all invoices) | E7: =AVERAGE('Invoice Sample'!H2:H121) -> 4.165
B8: Finance Mgr approval ($500+ only) | E8: =AVERAGEIF('Invoice Sample'!E2:E121,">=500",'Invoice Sample'!I2:I121) -> 3.559596
B9: Controller approval ($500+ only) | E9: =AVERAGEIF('Invoice Sample'!E2:E121,">=500",'Invoice Sample'!J2:J121) -> 4.189899
B10: Payment processing | E10: =AVERAGE('Invoice Sample'!K2:K121) -> 0.98
B13: Invoice mix by tier (this sample)
B14: Tier | C14: Count | D14: % of invoices | E14: Avg amount | F14: Avg total cycle days
B15: Tier 0 (<$500) | C15: =COUNTIF('Invoice Sample'!M2:M121,B15) -> 21 | D15: =C15/120 -> 0.175 | E15: =AVERAGEIF('Invoice Sample'!M2:M121,B15,'Invoice Sample'!E2:E121) -> 231.45143 | F15: =AVERAGEIF('Invoice Sample'!M2:M121,B15,'Invoice Sample'!L2:L121) -> 5.7333333
B16: Tier 1 ($500-$10K) | C16: =COUNTIF('Invoice Sample'!M2:M121,B16) -> 69 | D16: =C16/120 -> 0.575 | E16: =AVERAGEIF('Invoice Sample'!M2:M121,B16,'Invoice Sample'!E2:E121) -> 5153.9878 | F16: =AVERAGEIF('Invoice Sample'!M2:M121,B16,'Invoice Sample'!L2:L121) -> 13.953623
B17: Tier 2 ($10K-$50K) | C17: =COUNTIF('Invoice Sample'!M2:M121,B17) -> 25 | D17: =C17/120 -> 0.20833333 | E17: =AVERAGEIF('Invoice Sample'!M2:M121,B17,'Invoice Sample'!E2:E121) -> 29797.542 | F17: =AVERAGEIF('Invoice Sample'!M2:M121,B17,'Invoice Sample'!L2:L121) -> 15.124
B18: Tier 3 (>$50K) | C18: =COUNTIF('Invoice Sample'!M2:M121,B18) -> 5 | D18: =C18/120 -> 0.041666667 | E18: =AVERAGEIF('Invoice Sample'!M2:M121,B18,'Invoice Sample'!E2:E121) -> 93494.742 | F18: =AVERAGEIF('Invoice Sample'!M2:M121,B18,'Invoice Sample'!L2:L121) -> 15.78
B21: Current-state financial leakage (this sample, one month)
B22: Invoices with discount terms missing the 10-day window | E22: =COUNTIFS('Invoice Sample'!N2:N121,"Yes",'Invoice Sample'!O2:O121,"No") -> 36
B23: Discount $ forfeited this month | E23: =SUM('Invoice Sample'!Q2:Q121) -> 10401.238
B24: Invoices that missed Net 30 (late fee triggered) | E24: =COUNTIF('Invoice Sample'!P2:P121,"Yes") -> 0
B25: Late fee $ incurred this month | E25: =SUM('Invoice Sample'!R2:R121) -> 0

Sheet Future-State Model
B2: Future-State Model — tiered approvals + routing tool
B4: Levers (change these to test other scenarios)
B5: Required approvals — Tier 0 (<$500) | F5: Dept Mgr only (unchanged)
B6: Required approvals — Tier 1 ($500-$10K) | F6: Dept Mgr only
B7: Required approvals — Tier 2 ($10K-$50K) | F7: Dept Mgr + Finance Mgr
B8: Required approvals — Tier 3 (>$50K) | F8: Dept Mgr + Finance Mgr + Controller (unchanged)
B10: OCR/auto-capture time reduction — recurring vendors | F10: 0.8
B11: Data-entry time reduction — one-off / new vendors (not OCR-eligible) | F11: 0
B12: Approval queue-time reduction — routing tool + defined backup approvers | F12: 0.42
B13: Payment-processing time reduction — batch scheduling automation | F13: 0.3
B15: Implementation cost (one-time + Year 1)
B16: Routing/workflow tool — annual subscription | F16: 18000
B17: OCR/invoice-capture tool — annual subscription | F17: 9600
B18: One-time implementation & change-management effort | F18: 22000
B20: Projected stage durations
B21: Stage | C21: Current (obs.) | D21: Reduction | E21: Projected
B22: Data entry — recurring | C22: ='Bottleneck Analysis'!E5 -> 1.1872093 | D22: =F10 -> 0.8 | E22: =C22*(1-D22) -> 0.23744186
B23: Data entry — one-off | C23: ='Bottleneck Analysis'!E6 -> 1.5735294 | D23: =F11 -> 0 | E23: =C23*(1-D23) -> 1.5735294
B24: Dept Mgr approval | C24: ='Bottleneck Analysis'!E7 -> 4.165 | D24: =F12 -> 0.42 | E24: =C24*(1-D24) -> 2.4157
B25: Finance Mgr approval | C25: ='Bottleneck Analysis'!E8 -> 3.559596 | D25: =F12 -> 0.42 | E25: =C25*(1-D25) -> 2.0645657
B26: Controller approval | C26: ='Bottleneck Analysis'!E9 -> 4.189899 | D26: =F12 -> 0.42 | E26: =C26*(1-D26) -> 2.4301414
B27: Payment processing | C27: ='Bottleneck Analysis'!E10 -> 0.98 | D27: =F13 -> 0.3 | E27: =C27*(1-D27) -> 0.686

Sheet Future-State Projection
A1: Invoice ID | B1: Vendor Type | C1: Amount | D1: Tier | E1: Payment Terms | F1: Projected Data Entry | G1: Projected Dept Mgr | H1: Projected Finance Mgr | I1: Projected Controller | J1: Projected Payment | K1: Projected Total Cycle Days | L1: Discount Eligible? | M1: Discount Captured (future)? | N1: Late Fee (future)? | O1: Discount $ Now Captured | P1: Late Fee $ Now Avoided
A2: ='Invoice Sample'!A2 -> INV-2031 | B2: ='Invoice Sample'!C2 -> Recurring | C2: ='Invoice Sample'!E2 -> 13377.69 | D2: ='Invoice Sample'!M2 -> Tier 2 ($10K-$50K) | E2: ='Invoice Sample'!F2 -> Net 30 | F2: =IF(B2="Recurring",'Future-State Model'!E22,'Future-State Model'!E23) -> 0.23744186 | G2: ='Future-State Model'!E24 -> 2.4157 | H2: =IF(OR(D2="Tier 2 ($10K-$50K)",D2="Tier 3 (>$50K)"),'Future-State Model'!E25,0) -> 2.0645657 | I2: =IF(D2="Tier 3 (>$50K)",'Future-State Model'!E26,0) -> 0 | J2: ='Future-State Model'!E27 -> 0.686 | K2: =SUM(F2:J2) -> 5.4037075 | L2: =IF(E2="2/10 Net 30","Yes","No") -> No | M2: =IF(AND(L2="Yes",(F2+G2+H2+I2)<=10),"Yes","No") -> No | N2: =IF(K2>30,"Yes","No") -> No | O2: =IF(AND(L2="Yes",'Invoice Sample'!O2="No",M2="Yes"),C2*0.02,0) -> 0 | P2: =IF(AND('Invoice Sample'!P2="Yes",N2="No"),C2*0.015,0) -> 0
A3: ='Invoice Sample'!A3 -> INV-2032 | B3: ='Invoice Sample'!C3 -> Recurring | C3: ='Invoice Sample'!E3 -> 9287.72 | D3: ='Invoice Sample'!M3 -> Tier 1 ($500-$10K) | E3: ='Invoice Sample'!F3 -> Net 30 | F3: =IF(B3="Recurring",'Future-State Model'!E22,'Future-State Model'!E23) -> 0.23744186 | G3: ='Future-State Model'!E24 -> 2.4157 | H3: =IF(OR(D3="Tier 2 ($10K-$50K)",D3="Tier 3 (>$50K)"),'Future-State Model'!E25,0) -> 0 | I3: =IF(D3="Tier 3 (>$50K)",'Future-State Model'!E26,0) -> 0 | J3: ='Future-State Model'!E27 -> 0.686 | K3: =SUM(F3:J3) -> 3.3391419 | L3: =IF(E3="2/10 Net 30","Yes","No") -> No | M3: =IF(AND(L3="Yes",(F3+G3+H3+I3)<=10),"Yes","No") -> No | N3: =IF(K3>30,"Yes","No") -> No | O3: =IF(AND(L3="Yes",'Invoice Sample'!O3="No",M3="Yes"),C3*0.02,0) -> 0 | P3: =IF(AND('Invoice Sample'!P3="Yes",N3="No"),C3*0.015,0) -> 0
A4: ='Invoice Sample'!A4 -> INV-2033 | B4: ='Invoice Sample'!C4 -> One-off | C4: ='Invoice Sample'!E4 -> 29465.85 | D4: ='Invoice Sample'!M4 -> Tier 2 ($10K-$50K) | E4: ='Invoice Sample'!F4 -> Net 30 | F4: =IF(B4="Recurring",'Future-State Model'!E22,'Future-State Model'!E23) -> 1.5735294 | G4: ='Future-State Model'!E24 -> 2.4157 | H4: =IF(OR(D4="Tier 2 ($10K-$50K)",D4="Tier 3 (>$50K)"),'Future-State Model'!E25,0) -> 2.0645657 | I4: =IF(D4="Tier 3 (>$50K)",'Future-State Model'!E26,0) -> 0 | J4: ='Future-State Model'!E27 -> 0.686 | K4: =SUM(F4:J4) -> 6.7397951 | L4: =IF(E4="2/10 Net 30","Yes","No") -> No | M4: =IF(AND(L4="Yes",(F4+G4+H4+I4)<=10),"Yes","No") -> No | N4: =IF(K4>30,"Yes","No") -> No | O4: =IF(AND(L4="Yes",'Invoice Sample'!O4="No",M4="Yes"),C4*0.02,0) -> 0 | P4: =IF(AND('Invoice Sample'!P4="Yes",N4="No"),C4*0.015,0) -> 0
A5: ='Invoice Sample'!A5 -> INV-2034 | B5: ='Invoice Sample'!C5 -> Recurring | C5: ='Invoice Sample'!E5 -> 705.29 | D5: ='Invoice Sample'!M5 -> Tier 1 ($500-$10K) | E5: ='Invoice Sample'!F5 -> Net 30 | F5: =IF(B5="Recurring",'Future-State Model'!E22,'Future-State Model'!E23) -> 0.23744186 | G5: ='Future-State Model'!E24 -> 2.4157 | H5: =IF(OR(D5="Tier 2 ($10K-$50K)",D5="Tier 3 (>$50K)"),'Future-State Model'!E25,0) -> 0 | I5: =IF(D5="Tier 3 (>$50K)",'Future-State Model'!E26,0) -> 0 | J5: ='Future-State Model'!E27 -> 0.686 | K5: =SUM(F5:J5) -> 3.3391419 | L5: =IF(E5="2/10 Net 30","Yes","No") -> No | M5: =IF(AND(L5="Yes",(F5+G5+H5+I5)<=10),"Yes","No") -> No | N5: =IF(K5>30,"Yes","No") -> No | O5: =IF(AND(L5="Yes",'Invoice Sample'!O5="No",M5="Yes"),C5*0.02,0) -> 0 | P5: =IF(AND('Invoice Sample'!P5="Yes",N5="No"),C5*0.015,0) -> 0
A6: ='Invoice Sample'!A6 -> INV-2035 | B6: ='Invoice Sample'!C6 -> Recurring | C6: ='Invoice Sample'!E6 -> 384.61 | D6: ='Invoice Sample'!M6 -> Tier 0 (<$500) | E6: ='Invoice Sample'!F6 -> Net 30 | F6: =IF(B6="Recurring",'Future-State Model'!E22,'Future-State Model'!E23) -> 0.23744186 | G6: ='Future-State Model'!E24 -> 2.4157 | H6: =IF(OR(D6="Tier 2 ($10K-$50K)",D6="Tier 3 (>$50K)"),'Future-State Model'!E25,0) -> 0 | I6: =IF(D6="Tier 3 (>$50K)",'Future-State Model'!E26,0) -> 0 | J6: ='Future-State Model'!E27 -> 0.686 | K6: =SUM(F6:J6) -> 3.3391419 | L6: =IF(E6="2/10 Net 30","Yes","No") -> No | M6: =IF(AND(L6="Yes",(F6+G6+H6+I6)<=10),"Yes","No") -> No | N6: =IF(K6>30,"Yes","No") -> No | O6: =IF(AND(L6="Yes",'Invoice Sample'!O6="No",M6="Yes"),C6*0.02,0) -> 0 | P6: =IF(AND('Invoice Sample'!P6="Yes",N6="No"),C6*0.015,0) -> 0
A7: ='Invoice Sample'!A7 -> INV-2036 | B7: ='Invoice Sample'!C7 -> Recurring | C7: ='Invoice Sample'!E7 -> 75964.56 | D7: ='Invoice Sample'!M7 -> Tier 3 (>$50K) | E7: ='Invoice Sample'!F7 -> Net 30 | F7: =IF(B7="Recurring",'Future-State Model'!E22,'Future-State Model'!E23) -> 0.23744186 | G7: ='Future-State Model'!E24 -> 2.4157 | H7: =IF(OR(D7="Tier 2 ($10K-$50K)",D7="Tier 3 (>$50K)"),'Future-State Model'!E25,0) -> 2.0645657 | I7: =IF(D7="Tier 3 (>$50K)",'Future-State Model'!E26,0) -> 2.4301414 | J7: ='Future-State Model'!E27 -> 0.686 | K7: =SUM(F7:J7) -> 7.8338489 | L7: =IF(E7="2/10 Net 30","Yes","No") -> No | M7: =IF(AND(L7="Yes",(F7+G7+H7+I7)<=10),"Yes","No") -> No | N7: =IF(K7>30,"Yes","No") -> No | O7: =IF(AND(L7="Yes",'Invoice Sample'!O7="No",M7="Yes"),C7*0.02,0) -> 0 | P7: =IF(AND('Invoice Sample'!P7="Yes",N7="No"),C7*0.015,0) -> 0
A8: ='Invoice Sample'!A8 -> INV-2037 | B8: ='Invoice Sample'!C8 -> Recurring | C8: ='Invoice Sample'!E8 -> 16584.15 | D8: ='Invoice Sample'!M8 -> Tier 2 ($10K-$50K) | E8: ='Invoice Sample'!F8 -> 2/10 Net 30 | F8: =IF(B8="Recurring",'Future-State Model'!E22,'Future-State Model'!E23) -> 0.23744186 | G8: ='Future-State Model'!E24 -> 2.4157 | H8: =IF(OR(D8="Tier 2 ($10K-$50K)",D8="Tier 3 (>$50K)"),'Future-State Model'!E25,0) -> 2.0645657 | I8: =IF(D8="Tier 3 (>$50K)",'Future-State Model'!E26,0) -> 0 | J8: ='Future-State Model'!E27 -> 0.686 | K8: =SUM(F8:J8) -> 5.4037075 | L8: =IF(E8="2/10 Net 30","Yes","No") -> Yes | M8: =IF(AND(L8="Yes",(F8+G8+H8+I8)<=10),"Yes","No") -> Yes | N8: =IF(K8>30,"Yes","No") -> No | O8: =IF(AND(L8="Yes",'Invoice Sample'!O8="No",M8="Yes"),C8*0.02,0) -> 331.683 | P8: =IF(AND('Invoice Sample'!P8="Yes",N8="No"),C8*0.015,0) -> 0
A9: ='Invoice Sample'!A9 -> INV-2038 | B9: ='Invoice Sample'!C9 -> One-off | C9: ='Invoice Sample'!E9 -> 22636.85 | D9: ='Invoice Sample'!M9 -> Tier 2 ($10K-$50K) | E9: ='Invoice Sample'!F9 -> Net 30 | F9: =IF(B9="Recurring",'Future-State Model'!E22,'Future-State Model'!E23) -> 1.5735294 | G9: ='Future-State Model'!E24 -> 2.4157 | H9: =IF(OR(D9="Tier 2 ($10K-$50K)",D9="Tier 3 (>$50K)"),'Future-State Model'!E25,0) -> 2.0645657 | I9: =IF(D9="Tier 3 (>$50K)",'Future-State Model'!E26,0) -> 0 | J9: ='Future-State Model'!E27 -> 0.686 | K9: =SUM(F9:J9) -> 6.7397951 | L9: =IF(E9="2/10 Net 30","Yes","No") -> No | M9: =IF(AND(L9="Yes",(F9+G9+H9+I9)<=10),"Yes","No") -> No | N9: =IF(K9>30,"Yes","No") -> No | O9: =IF(AND(L9="Yes",'Invoice Sample'!O9="No",M9="Yes"),C9*0.02,0) -> 0 | P9: =IF(AND('Invoice Sample'!P9="Yes",N9="No"),C9*0.015,0) -> 0
A10: ='Invoice Sample'!A10 -> INV-2039 | B10: ='Invoice Sample'!C10 -> One-off | C10: ='Invoice Sample'!E10 -> 131.44 | D10: ='Invoice Sample'!M10 -> Tier 0 (<$500) | E10: ='Invoice Sample'!F10 -> Net 30 | F10: =IF(B10="Recurring",'Future-State Model'!E22,'Future-State Model'!E23) -> 1.5735294 | G10: ='Future-State Model'!E24 -> 2.4157 | H10: =IF(OR(D10="Tier 2 ($10K-$50K)",D10="Tier 3 (>$50K)"),'Future-State Model'!E25,0) -> 0 | I10: =IF(D10="Tier 3 (>$50K)",'Future-State Model'!E26,0) -> 0 | J10: ='Future-State Model'!E27 -> 0.686 | K10: =SUM(F10:J10) -> 4.6752294 | L10: =IF(E10="2/10 Net 30","Yes","No") -> No | M10: =IF(AND(L10="Yes",(F10+G10+H10+I10)<=10),"Yes","No") -> No | N10: =IF(K10>30,"Yes","No") -> No | O10: =IF(AND(L10="Yes",'Invoice Sample'!O10="No",M10="Yes"),C10*0.02,0) -> 0 | P10: =IF(AND('Invoice Sample'!P10="Yes",N10="No"),C10*0.015,0) -> 0
A11: ='Invoice Sample'!A11 -> INV-2040 | B11: ='Invoice Sample'!C11 -> One-off | C11: ='Invoice Sample'!E11 -> 3447.76 | D11: ='Invoice Sample'!M11 -> Tier 1 ($500-$10K) | E11: ='Invoice Sample'!F11 -> Net 30 | F11: =IF(B11="Recurring",'Future-State Model'!E22,'Future-State Model'!E23) -> 1.5735294 | G11: ='Future-State Model'!E24 -> 2.4157 | H11: =IF(OR(D11="Tier 2 ($10K-$50K)",D11="Tier 3 (>$50K)"),'Future-State Model'!E25,0) -> 0 | I11: =IF(D11="Tier 3 (>$50K)",'Future-State Model'!E26,0) -> 0 | J11: ='Future-State Model'!E27 -> 0.686 | K11: =SUM(F11:J11) -> 4.6752294 | L11: =IF(E11="2/10 Net 30","Yes","No") -> No | M11: =IF(AND(L11="Yes",(F11+G11+H11+I11)<=10),"Yes","No") -> No | N11: =IF(K11>30,"Yes","No") -> No | O11: =IF(AND(L11="Yes",'Invoice Sample'!O11="No",M11="Yes"),C11*0.02,0) -> 0 | P11: =IF(AND('Invoice Sample'!P11="Yes",N11="No"),C11*0.015,0) -> 0
A12: ='Invoice Sample'!A12 -> INV-2041 | B12: ='Invoice Sample'!C12 -> Recurring | C12: ='Invoice Sample'!E12 -> 1657.29 | D12: ='Invoice Sample'!M12 -> Tier 1 ($500-$10K) | E12: ='Invoice Sample'!F12 -> Net 30 | F12: =IF(B12="Recurring",'Future-State Model'!E22,'Future-State Model'!E23) -> 0.23744186 | G12: ='Future-State Model'!E24 -> 2.4157 | H12: =IF(OR(D12="Tier 2 ($10K-$50K)",D12="Tier 3 (>$50K)"),'Future-State Model'!E25,0) -> 0 | I12: =IF(D12="Tier 3 (>$50K)",'Future-State Model'!E26,0) -> 0 | J12: ='Future-State Model'!E27 -> 0.686 | K12: =SUM(F12:J12) -> 3.3391419 | L12: =IF(E12="2/10 Net 30","Yes","No") -> No | M12: =IF(AND(L12="Yes",(F12+G12+H12+I12)<=10),"Yes","No") -> No | N12: =IF(K12>30,"Yes","No") -> No | O12: =IF(AND(L12="Yes",'Invoice Sample'!O12="No",M12="Yes"),C12*0.02,0) -> 0 | P12: =IF(AND('Invoice Sample'!P12="Yes",N12="No"),C12*0.015,0) -> 0
A13: ='Invoice Sample'!A13 -> INV-2042 | B13: ='Invoice Sample'!C13 -> Recurring | C13: ='Invoice Sample'!E13 -> 14950.03 | D13: ='Invoice Sample'!M13 -> Tier 2 ($10K-$50K) | E13: ='Invoice Sample'!F13 -> Net 30 | F13: =IF(B13="Recurring",'Future-State Model'!E22,'Future-State Model'!E23) -> 0.23744186 | G13: ='Future-State Model'!E24 -> 2.4157 | H13: =IF(OR(D13="Tier 2 ($10K-$50K)",D13="Tier 3 (>$50K)"),'Future-State Model'!E25,0) -> 2.0645657 | I13: =IF(D13="Tier 3 (>$50K)",'Future-State Model'!E26,0) -> 0 | J13: ='Future-State Model'!E27 -> 0.686 | K13: =SUM(F13:J13) -> 5.4037075 | L13: =IF(E13="2/10 Net 30","Yes","No") -> No | M13: =IF(AND(L13="Yes",(F13+G13+H13+I13)<=10),"Yes","No") -> No | N13: =IF(K13>30,"Yes","No") -> No | O13: =IF(AND(L13="Yes",'Invoice Sample'!O13="No",M13="Yes"),C13*0.02,0) -> 0 | P13: =IF(AND('Invoice Sample'!P13="Yes",N13="No"),C13*0.015,0) -> 0
A14: ='Invoice Sample'!A14 -> INV-2043 | B14: ='Invoice Sample'!C14 -> Recurring | C14: ='Invoice Sample'!E14 -> 736.14 | D14: ='Invoice Sample'!M14 -> Tier 1 ($500-$10K) | E14: ='Invoice Sample'!F14 -> Net 30 | F14: =IF(B14="Recurring",'Future-State Model'!E22,'Future-State Model'!E23) -> 0.23744186 | G14: ='Future-State Model'!E24 -> 2.4157 | H14: =IF(OR(D14="Tier 2 ($10K-$50K)",D14="Tier 3 (>$50K)"),'Future-State Model'!E25,0) -> 0 | I14: =IF(D14="Tier 3 (>$50K)",'Future-State Model'!E26,0) -> 0 | J14: ='Future-State Model'!E27 -> 0.686 | K14: =SUM(F14:J14) -> 3.3391419 | L14: =IF(E14="2/10 Net 30","Yes","No") -> No | M14: =IF(AND(L14="Yes",(F14+G14+H14+I14)<=10),"Yes","No") -> No | N14: =IF(K14>30,"Yes","No") -> No | O14: =IF(AND(L14="Yes",'Invoice Sample'!O14="No",M14="Yes"),C14*0.02,0) -> 0 | P14: =IF(AND('Invoice Sample'!P14="Yes",N14="No"),C14*0.015,0) -> 0
A15: ='Invoice Sample'!A15 -> INV-2044 | B15: ='Invoice Sample'!C15 -> Recurring | C15: ='Invoice Sample'!E15 -> 42173.63 | D15: ='Invoice Sample'!M15 -> Tier 2 ($10K-$50K) | E15: ='Invoice Sample'!F15 -> Net 30 | F15: =IF(B15="Recurring",'Future-State Model'!E22,'Future-State Model'!E23) -> 0.23744186 | G15: ='Future-State Model'!E24 -> 2.4157 | H15: =IF(OR(D15="Tier 2 ($10K-$50K)",D15="Tier 3 (>$50K)"),'Future-State Model'!E25,0) -> 2.0645657 | I15: =IF(D15="Tier 3 (>$50K)",'Future-State Model'!E26,0) -> 0 | J15: ='Future-State Model'!E27 -> 0.686 | K15: =SUM(F15:J15) -> 5.4037075 | L15: =IF(E15="2/10 Net 30","Yes","No") -> No | M15: =IF(AND(L15="Yes",(F15+G15+H15+I15)<=10),"Yes","No") -> No | N15: =IF(K15>30,"Yes","No") -> No | O15: =IF(AND(L15="Yes",'Invoice Sample'!O15="No",M15="Yes"),C15*0.02,0) -> 0 | P15: =IF(AND('Invoice Sample'!P15="Yes",N15="No"),C15*0.015,0) -> 0
A16: ='Invoice Sample'!A16 -> INV-2045 | B16: ='Invoice Sample'!C16 -> Recurring | C16: ='Invoice Sample'!E16 -> 6256.54 | D16: ='Invoice Sample'!M16 -> Tier 1 ($500-$10K) | E16: ='Invoice Sample'!F16 -> Net 30 | F16: =IF(B16="Recurring",'Future-State Model'!E22,'Future-State Model'!E23) -> 0.23744186 | G16: ='Future-State Model'!E24 -> 2.4157 | H16: =IF(OR(D16="Tier 2 ($10K-$50K)",D16="Tier 3 (>$50K)"),'Future-State Model'!E25,0) -> 0 | I16: =IF(D16="Tier 3 (>$50K)",'Future-State Model'!E26,0) -> 0 | J16: ='Future-State Model'!E27 -> 0.686 | K16: =SUM(F16:J16) -> 3.3391419 | L16: =IF(E16="2/10 Net 30","Yes","No") -> No | M16: =IF(AND(L16="Yes",(F16+G16+H16+I16)<=10),"Yes","No") -> No | N16: =IF(K16>30,"Yes","No") -> No | O16: =IF(AND(L16="Yes",'Invoice Sample'!O16="No",M16="Yes"),C16*0.02,0) -> 0 | P16: =IF(AND('Invoice Sample'!P16="Yes",N16="No"),C16*0.015,0) -> 0
A17: ='Invoice Sample'!A17 -> INV-2046 | B17: ='Invoice Sample'!C17 -> Recurring | C17: ='Invoice Sample'!E17 -> 2748.06 | D17: ='Invoice Sample'!M17 -> Tier 1 ($500-$10K) | E17: ='Invoice Sample'!F17 -> Net 30 | F17: =IF(B17="Recurring",'Future-State Model'!E22,'Future-State Model'!E23) -> 0.23744186 | G17: ='Future-State Model'!E24 -> 2.4157 | H17: =IF(OR(D17="Tier 2 ($10K-$50K)",D17="Tier 3 (>$50K)"),'Future-State Model'!E25,0) -> 0 | I17: =IF(D17="Tier 3 (>$50K)",'Future-State Model'!E26,0) -> 0 | J17: ='Future-State Model'!E27 -> 0.686 | K17: =SUM(F17:J17) -> 3.3391419 | L17: =IF(E17="2/10 Net 30","Yes","No") -> No | M17: =IF(AND(L17="Yes",(F17+G17+H17+I17)<=10),"Yes","No") -> No | N17: =IF(K17>30,"Yes","No") -> No | O17: =IF(AND(L17="Yes",'Invoice Sample'!O17="No",M17="Yes"),C17*0.02,0) -> 0 | P17: =IF(AND('Invoice Sample'!P17="Yes",N17="No"),C17*0.015,0) -> 0
A18: ='Invoice Sample'!A18 -> INV-2047 | B18: ='Invoice Sample'!C18 -> One-off | C18: ='Invoice Sample'!E18 -> 1866.64 | D18: ='Invoice Sample'!M18 -> Tier 1 ($500-$10K) | E18: ='Invoice Sample'!F18 -> Net 30 | F18: =IF(B18="Recurring",'Future-State Model'!E22,'Future-State Model'!E23) -> 1.5735294 | G18: ='Future-State Model'!E24 -> 2.4157 | H18: =IF(OR(D18="Tier 2 ($10K-$50K)",D18="Tier 3 (>$50K)"),'Future-State Model'!E25,0) -> 0 | I18: =IF(D18="Tier 3 (>$50K)",'Future-State Model'!E26,0) -> 0 | J18: ='Future-State Model'!E27 -> 0.686 | K18: =SUM(F18:J18) -> 4.6752294 | L18: =IF(E18="2/10 Net 30","Yes","No") -> No | M18: =IF(AND(L18="Yes",(F18+G18+H18+I18)<=10),"Yes","No") -> No | N18: =IF(K18>30,"Yes","No") -> No | O18: =IF(AND(L18="Yes",'Invoice Sample'!O18="No",M18="Yes"),C18*0.02,0) -> 0 | P18: =IF(AND('Invoice Sample'!P18="Yes",N18="No"),C18*0.015,0) -> 0
A19: ='Invoice Sample'!A19 -> INV-2048 | B19: ='Invoice Sample'!C19 -> Recurring | C19: ='Invoice Sample'!E19 -> 102.37 | D19: ='Invoice Sample'!M19 -> Tier 0 (<$500) | E19: ='Invoice Sample'!F19 -> Net 30 | F19: =IF(B19="Recurring",'Future-State Model'!E22,'Future-State Model'!E23) -> 0.23744186 | G19: ='Future-State Model'!E24 -> 2.4157 | H19: =IF(OR(D19="Tier 2 ($10K-$50K)",D19="Tier 3 (>$50K)"),'Future-State Model'!E25,0) -> 0 | I19: =IF(D19="Tier 3 (>$50K)",'Future-State Model'!E26,0) -> 0 | J19: ='Future-State Model'!E27 -> 0.686 | K19: =SUM(F19:J19) -> 3.3391419 | L19: =IF(E19="2/10 Net 30","Yes","No") -> No | M19: =IF(AND(L19="Yes",(F19+G19+H19+I19)<=10),"Yes","No") -> No | N19: =IF(K19>30,"Yes","No") -> No | O19: =IF(AND(L19="Yes",'Invoice Sample'!O19="No",M19="Yes"),C19*0.02,0) -> 0 | P19: =IF(AND('Invoice Sample'!P19="Yes",N19="No"),C19*0.015,0) -> 0
A20: ='Invoice Sample'!A20 -> INV-2049 | B20: ='Invoice Sample'!C20 -> Recurring | C20: ='Invoice Sample'!E20 -> 44044.41 | D20: ='Invoice Sample'!M20 -> Tier 2 ($10K-$50K) | E20: ='Invoice Sample'!F20 -> 2/10 Net 30 | F20: =IF(B20="Recurring",'Future-State Model'!E22,'Future-State Model'!E23) -> 0.23744186 | G20: ='Future-State Model'!E24 -> 2.4157 | H20: =IF(OR(D20="Tier 2 ($10K-$50K)",D20="Tier 3 (>$50K)"),'Future-State Model'!E25,0) -> 2.0645657 | I20: =IF(D20="Tier 3 (>$50K)",'Future-State Model'!E26,0) -> 0 | J20: ='Future-State Model'!E27 -> 0.686 | K20: =SUM(F20:J20) -> 5.4037075 | L20: =IF(E20="2/10 Net 30","Yes","No") -> Yes | M20: =IF(AND(L20="Yes",(F20+G20+H20+I20)<=10),"Yes","No") -> Yes | N20: =IF(K20>30,"Yes","No") -> No | O20: =IF(AND(L20="Yes",'Invoice Sample'!O20="No",M20="Yes"),C20*0.02,0) -> 880.8882 | P20: =IF(AND('Invoice Sample'!P20="Yes",N20="No"),C20*0.015,0) -> 0
A21: ='Invoice Sample'!A21 -> INV-2050 | B21: ='Invoice Sample'!C21 -> Recurring | C21: ='Invoice Sample'!E21 -> 1465.78 | D21: ='Invoice Sample'!M21 -> Tier 1 ($500-$10K) | E21: ='Invoice Sample'!F21 -> Net 30 | F21: =IF(B21="Recurring",'Future-State Model'!E22,'Future-State Model'!E23) -> 0.23744186 | G21: ='Future-State Model'!E24 -> 2.4157 | H21: =IF(OR(D21="Tier 2 ($10K-$50K)",D21="Tier 3 (>$50K)"),'Future-State Model'!E25,0) -> 0 | I21: =IF(D21="Tier 3 (>$50K)",'Future-State Model'!E26,0) -> 0 | J21: ='Future-State Model'!E27 -> 0.686 | K21: =SUM(F21:J21) -> 3.3391419 | L21: =IF(E21="2/10 Net 30","Yes","No") -> No | M21: =IF(AND(L21="Yes",(F21+G21+H21+I21)<=10),"Yes","No") -> No | N21: =IF(K21>30,"Yes","No") -> No | O21: =IF(AND(L21="Yes",'Invoice Sample'!O21="No",M21="Yes"),C21*0.02,0) -> 0 | P21: =IF(AND('Invoice Sample'!P21="Yes",N21="No"),C21*0.015,0) -> 0
A22: ='Invoice Sample'!A22 -> INV-2051 | B22: ='Invoice Sample'!C22 -> One-off | C22: ='Invoice Sample'!E22 -> 41178.32 | D22: ='Invoice Sample'!M22 -> Tier 2 ($10K-$50K) | E22: ='Invoice Sample'!F22 -> Net 30 | F22: =IF(B22="Recurring",'Future-State Model'!E22,'Future-State Model'!E23) -> 1.5735294 | G22: ='Future-State Model'!E24 -> 2.4157 | H22: =IF(OR(D22="Tier 2 ($10K-$50K)",D22="Tier 3 (>$50K)"),'Future-State Model'!E25,0) -> 2.0645657 | I22: =IF(D22="Tier 3 (>$50K)",'Future-State Model'!E26,0) -> 0 | J22: ='Future-State Model'!E27 -> 0.686 | K22: =SUM(F22:J22) -> 6.7397951 | L22: =IF(E22="2/10 Net 30","Yes","No") -> No | M22: =IF(AND(L22="Yes",(F22+G22+H22+I22)<=10),"Yes","No") -> No | N22: =IF(K22>30,"Yes","No") -> No | O22: =IF(AND(L22="Yes",'Invoice Sample'!O22="No",M22="Yes"),C22*0.02,0) -> 0 | P22: =IF(AND('Invoice Sample'!P22="Yes",N22="No"),C22*0.015,0) -> 0
A23: ='Invoice Sample'!A23 -> INV-2052 | B23: ='Invoice Sample'!C23 -> Recurring | C23: ='Invoice Sample'!E23 -> 6575.21 | D23: ='Invoice Sample'!M23 -> Tier 1 ($500-$10K) | E23: ='Invoice Sample'!F23 -> 2/10 Net 30 | F23: =IF(B23="Recurring",'Future-State Model'!E22,'Future-State Model'!E23) -> 0.23744186 | G23: ='Future-State Model'!E24 -> 2.4157 | H23: =IF(OR(D23="Tier 2 ($10K-$50K)",D23="Tier 3 (>$50K)"),'Future-State Model'!E25,0) -> 0 | I23: =IF(D23="Tier 3 (>$50K)",'Future-State Model'!E26,0) -> 0 | J23: ='Future-State Model'!E27 -> 0.686 | K23: =SUM(F23:J23) -> 3.3391419 | L23: =IF(E23="2/10 Net 30","Yes","No") -> Yes | M23: =IF(AND(L23="Yes",(F23+G23+H23+I23)<=10),"Yes","No") -> Yes | N23: =IF(K23>30,"Yes","No") -> No | O23: =IF(AND(L23="Yes",'Invoice Sample'!O23="No",M23="Yes"),C23*0.02,0) -> 131.5042 | P23: =IF(AND('Invoice Sample'!P23="Yes",N23="No"),C23*0.015,0) -> 0
A24: ='Invoice Sample'!A24 -> INV-2053 | B24: ='Invoice Sample'!C24 -> Recurring | C24: ='Invoice Sample'!E24 -> 76562.49 | D24: ='Invoice Sample'!M24 -> Tier 3 (>$50K) | E24: ='Invoice Sample'!F24 -> Net 30 | F24: =IF(B24="Recurring",'Future-State Model'!E22,'Future-State Model'!E23) -> 0.23744186 | G24: ='Future-State Model'!E24 -> 2.4157 | H24: =IF(OR(D24="Tier 2 ($10K-$50K)",D24="Tier 3 (>$50K)"),'Future-State Model'!E25,0) -> 2.0645657 | I24: =IF(D24="Tier 3 (>$50K)",'Future-State Model'!E26,0) -> 2.4301414 | J24: ='Future-State Model'!E27 -> 0.686 | K24: =SUM(F24:J24) -> 7.8338489 | L24: =IF(E24="2/10 Net 30","Yes","No") -> No | M24: =IF(AND(L24="Yes",(F24+G24+H24+I24)<=10),"Yes","No") -> No | N24: =IF(K24>30,"Yes","No") -> No | O24: =IF(AND(L24="Yes",'Invoice Sample'!O24="No",M24="Yes"),C24*0.02,0) -> 0 | P24: =IF(AND('Invoice Sample'!P24="Yes",N24="No"),C24*0.015,0) -> 0
A25: ='Invoice Sample'!A25 -> INV-2054 | B25: ='Invoice Sample'!C25 -> Recurring | C25: ='Invoice Sample'!E25 -> 36102.84 | D25: ='Invoice Sample'!M25 -> Tier 2 ($10K-$50K) | E25: ='Invoice Sample'!F25 -> Net 30 | F25: =IF(B25="Recurring",'Future-State Model'!E22,'Future-State Model'!E23) -> 0.23744186 | G25: ='Future-State Model'!E24 -> 2.4157 | H25: =IF(OR(D25="Tier 2 ($10K-$50K)",D25="Tier 3 (>$50K)"),'Future-State Model'!E25,0) -> 2.0645657 | I25: =IF(D25="Tier 3 (>$50K)",'Future-State Model'!E26,0) -> 0 | J25: ='Future-State Model'!E27 -> 0.686 | K25: =SUM(F25:J25) -> 5.4037075 | L25: =IF(E25="2/10 Net 30","Yes","No") -> No | M25: =IF(AND(L25="Yes",(F25+G25+H25+I25)<=10),"Yes","No") -> No | N25: =IF(K25>30,"Yes","No") -> No | O25: =IF(AND(L25="Yes",'Invoice Sample'!O25="No",M25="Yes"),C25*0.02,0) -> 0 | P25: =IF(AND('Invoice Sample'!P25="Yes",N25="No"),C25*0.015,0) -> 0
A26: ='Invoice Sample'!A26 -> INV-2055 | B26: ='Invoice Sample'!C26 -> Recurring | C26: ='Invoice Sample'!E26 -> 15283.98 | D26: ='Invoice Sample'!M26 -> Tier 2 ($10K-$50K) | E26: ='Invoice Sample'!F26 -> Net 30 | F26: =IF(B26="Recurring",'Future-State Model'!E22,'Future-State Model'!E23) -> 0.23744186 | G26: ='Future-State Model'!E24 -> 2.4157 | H26: =IF(OR(D26="Tier 2 ($10K-$50K)",D26="Tier 3 (>$50K)"),'Future-State Model'!E25,0) -> 2.0645657 | I26: =IF(D26="Tier 3 (>$50K)",'Future-State Model'!E26,0) -> 0 | J26: ='Future-State Model'!E27 -> 0.686 | K26: =SUM(F26:J26) -> 5.4037075 | L26: =IF(E26="2/10 Net 30","Yes","No") -> No | M26: =IF(AND(L26="Yes",(F26+G26+H26+I26)<=10),"Yes","No") -> No | N26: =IF(K26>30,"Yes","No") -> No | O26: =IF(AND(L26="Yes",'Invoice Sample'!O26="No",M26="Yes"),C26*0.02,0) -> 0 | P26: =IF(AND('Invoice Sample'!P26="Yes",N26="No"),C26*0.015,0) -> 0
A27: ='Invoice Sample'!A27 -> INV-2056 | B27: ='Invoice Sample'!C27 -> One-off | C27: ='Invoice Sample'!E27 -> 6139.39 | D27: ='Invoice Sample'!M27 -> Tier 1 ($500-$10K) | E27: ='Invoice Sample'!F27 -> Net 30 | F27: =IF(B27="Recurring",'Future-State Model'!E22,'Future-State Model'!E23) -> 1.5735294 | G27: ='Future-State Model'!E24 -> 2.4157 | H27: =IF(OR(D27="Tier 2 ($10K-$50K)",D27="Tier 3 (>$50K)"),'Future-State Model'!E25,0) -> 0 | I27: =IF(D27="Tier 3 (>$50K)",'Future-State Model'!E26,0) -> 0 | J27: ='Future-State Model'!E27 -> 0.686 | K27: =SUM(F27:J27) -> 4.6752294 | L27: =IF(E27="2/10 Net 30","Yes","No") -> No | M27: =IF(AND(L27="Yes",(F27+G27+H27+I27)<=10),"Yes","No") -> No | N27: =IF(K27>30,"Yes","No") -> No | O27: =IF(AND(L27="Yes",'Invoice Sample'!O27="No",M27="Yes"),C27*0.02,0) -> 0 | P27: =IF(AND('Invoice Sample'!P27="Yes",N27="No"),C27*0.015,0) -> 0
A28: ='Invoice Sample'!A28 -> INV-2057 | B28: ='Invoice Sample'!C28 -> Recurring | C28: ='Invoice Sample'!E28 -> 5866.47 | D28: ='Invoice Sample'!M28 -> Tier 1 ($500-$10K) | E28: ='Invoice Sample'!F28 -> Net 30 | F28: =IF(B28="Recurring",'Future-State Model'!E22,'Future-State Model'!E23) -> 0.23744186 | G28: ='Future-State Model'!E24 -> 2.4157 | H28: =IF(OR(D28="Tier 2 ($10K-$50K)",D28="Tier 3 (>$50K)"),'Future-State Model'!E25,0) -> 0 | I28: =IF(D28="Tier 3 (>$50K)",'Future-State Model'!E26,0) -> 0 | J28: ='Future-State Model'!E27 -> 0.686 | K28: =SUM(F28:J28) -> 3.3391419 | L28: =IF(E28="2/10 Net 30","Yes","No") -> No | M28: =IF(AND(L28="Yes",(F28+G28+H28+I28)<=10),"Yes","No") -> No | N28: =IF(K28>30,"Yes","No") -> No | O28: =IF(AND(L28="Yes",'Invoice Sample'!O28="No",M28="Yes"),C28*0.02,0) -> 0 | P28: =IF(AND('Invoice Sample'!P28="Yes",N28="No"),C28*0.015,0) -> 0
A29: ='Invoice Sample'!A29 -> INV-2058 | B29: ='Invoice Sample'!C29 -> Recurring | C29: ='Invoice Sample'!E29 -> 130.17 | D29: ='Invoice Sample'!M29 -> Tier 0 (<$500) | E29: ='Invoice Sample'!F29 -> 2/10 Net 30 | F29: =IF(B29="Recurring",'Future-State Model'!E22,'Future-State Model'!E23) -> 0.23744186 | G29: ='Future-State Model'!E24 -> 2.4157 | H29: =IF(OR(D29="Tier 2 ($10K-$50K)",D29="Tier 3 (>$50K)"),'Future-State Model'!E25,0) -> 0 | I29: =IF(D29="Tier 3 (>$50K)",'Future-State Model'!E26,0) -> 0 | J29: ='Future-State Model'!E27 -> 0.686 | K29: =SUM(F29:J29) -> 3.3391419 | L29: =IF(E29="2/10 Net 30","Yes","No") -> Yes | M29: =IF(AND(L29="Yes",(F29+G29+H29+I29)<=10),"Yes","No") -> Yes | N29: =IF(K29>30,"Yes","No") -> No | O29: =IF(AND(L29="Yes",'Invoice Sample'!O29="No",M29="Yes"),C29*0.02,0) -> 0 | P29: =IF(AND('Invoice Sample'!P29="Yes",N29="No"),C29*0.015,0) -> 0
A30: ='Invoice Sample'!A30 -> INV-2059 | B30: ='Invoice Sample'!C30 -> One-off | C30: ='Invoice Sample'!E30 -> 219.79 | D30: ='Invoice Sample'!M30 -> Tier 0 (<$500) | E30: ='Invoice Sample'!F30 -> Net 30 | F30: =IF(B30="Recurring",'Future-State Model'!E22,'Future-State Model'!E23) -> 1.5735294 | G30: ='Future-State Model'!E24 -> 2.4157 | H30: =IF(OR(D30="Tier 2 ($10K-$50K)",D30="Tier 3 (>$50K)"),'Future-State Model'!E25,0) -> 0 | I30: =IF(D30="Tier 3 (>$50K)",'Future-State Model'!E26,0) -> 0 | J30: ='Future-State Model'!E27 -> 0.686 | K30: =SUM(F30:J30) -> 4.6752294 | L30: =IF(E30="2/10 Net 30","Yes","No") -> No | M30: =IF(AND(L30="Yes",(F30+G30+H30+I30)<=10),"Yes","No") -> No | N30: =IF(K30>30,"Yes","No") -> No | O30: =IF(AND(L30="Yes",'Invoice Sample'!O30="No",M30="Yes"),C30*0.02,0) -> 0 | P30: =IF(AND('Invoice Sample'!P30="Yes",N30="No"),C30*0.015,0) -> 0
A31: ='Invoice Sample'!A31 -> INV-2060 | B31: ='Invoice Sample'!C31 -> Recurring | C31: ='Invoice Sample'!E31 -> 1903.79 | D31: ='Invoice Sample'!M31 -> Tier 1 ($500-$10K) | E31: ='Invoice Sample'!F31 -> Net 30 | F31: =IF(B31="Recurring",'Future-State Model'!E22,'Future-State Model'!E23) -> 0.23744186 | G31: ='Future-State Model'!E24 -> 2.4157 | H31: =IF(OR(D31="Tier 2 ($10K-$50K)",D31="Tier 3 (>$50K)"),'Future-State Model'!E25,0) -> 0 | I31: =IF(D31="Tier 3 (>$50K)",'Future-State Model'!E26,0) -> 0 | J31: ='Future-State Model'!E27 -> 0.686 | K31: =SUM(F31:J31) -> 3.3391419 | L31: =IF(E31="2/10 Net 30","Yes","No") -> No | M31: =IF(AND(L31="Yes",(F31+G31+H31+I31)<=10),"Yes","No") -> No | N31: =IF(K31>30,"Yes","No") -> No | O31: =IF(AND(L31="Yes",'Invoice Sample'!O31="No",M31="Yes"),C31*0.02,0) -> 0 | P31: =IF(AND('Invoice Sample'!P31="Yes",N31="No"),C31*0.015,0) -> 0
A32: ='Invoice Sample'!A32 -> INV-2061 | B32: ='Invoice Sample'!C32 -> One-off | C32: ='Invoice Sample'!E32 -> 25054 | D32: ='Invoice Sample'!M32 -> Tier 2 ($10K-$50K) | E32: ='Invoice Sample'!F32 -> Net 30 | F32: =IF(B32="Recurring",'Future-State Model'!E22,'Future-State Model'!E23) -> 1.5735294 | G32: ='Future-State Model'!E24 -> 2.4157 | H32: =IF(OR(D32="Tier 2 ($10K-$50K)",D32="Tier 3 (>$50K)"),'Future-State Model'!E25,0) -> 2.0645657 | I32: =IF(D32="Tier 3 (>$50K)",'Future-State Model'!E26,0) -> 0 | J32: ='Future-State Model'!E27 -> 0.686 | K32: =SUM(F32:J32) -> 6.7397951 | L32: =IF(E32="2/10 Net 30","Yes","No") -> No | M32: =IF(AND(L32="Yes",(F32+G32+H32+I32)<=10),"Yes","No") -> No | N32: =IF(K32>30,"Yes","No") -> No | O32: =IF(AND(L32="Yes",'Invoice Sample'!O32="No",M32="Yes"),C32*0.02,0) -> 0 | P32: =IF(AND('Invoice Sample'!P32="Yes",N32="No"),C32*0.015,0) -> 0
A33: ='Invoice Sample'!A33 -> INV-2062 | B33: ='Invoice Sample'!C33 -> Recurring | C33: ='Invoice Sample'!E33 -> 98026.75 | D33: ='Invoice Sample'!M33 -> Tier 3 (>$50K) | E33: ='Invoice Sample'!F33 -> 2/10 Net 30 | F33: =IF(B33="Recurring",'Future-State Model'!E22,'Future-State Model'!E23) -> 0.23744186 | G33: ='Future-State Model'!E24 -> 2.4157 | H33: =IF(OR(D33="Tier 2 ($10K-$50K)",D33="Tier 3 (>$50K)"),'Future-State Model'!E25,0) -> 2.0645657 | I33: =IF(D33="Tier 3 (>$50K)",'Future-State Model'!E26,0) -> 2.4301414 | J33: ='Future-State Model'!E27 -> 0.686 | K33: =SUM(F33:J33) -> 7.8338489 | L33: =IF(E33="2/10 Net 30","Yes","No") -> Yes | M33: =IF(AND(L33="Yes",(F33+G33+H33+I33)<=10),"Yes","No") -> Yes | N33: =IF(K33>30,"Yes","No") -> No | O33: =IF(AND(L33="Yes",'Invoice Sample'!O33="No",M33="Yes"),C33*0.02,0) -> 0 | P33: =IF(AND('Invoice Sample'!P33="Yes",N33="No"),C33*0.015,0) -> 0
A34: ='Invoice Sample'!A34 -> INV-2063 | B34: ='Invoice Sample'!C34 -> Recurring | C34: ='Invoice Sample'!E34 -> 7921.51 | D34: ='Invoice Sample'!M34 -> Tier 1 ($500-$10K) | E34: ='Invoice Sample'!F34 -> 2/10 Net 30 | F34: =IF(B34="Recurring",'Future-State Model'!E22,'Future-State Model'!E23) -> 0.23744186 | G34: ='Future-State Model'!E24 -> 2.4157 | H34: =IF(OR(D34="Tier 2 ($10K-$50K)",D34="Tier 3 (>$50K)"),'Future-State Model'!E25,0) -> 0 | I34: =IF(D34="Tier 3 (>$50K)",'Future-State Model'!E26,0) -> 0 | J34: ='Future-State Model'!E27 -> 0.686 | K34: =SUM(F34:J34) -> 3.3391419 | L34: =IF(E34="2/10 Net 30","Yes","No") -> Yes | M34: =IF(AND(L34="Yes",(F34+G34+H34+I34)<=10),"Yes","No") -> Yes | N34: =IF(K34>30,"Yes","No") -> No | O34: =IF(AND(L34="Yes",'Invoice Sample'!O34="No",M34="Yes"),C34*0.02,0) -> 158.4302 | P34: =IF(AND('Invoice Sample'!P34="Yes",N34="No"),C34*0.015,0) -> 0
A35: ='Invoice Sample'!A35 -> INV-2064 | B35: ='Invoice Sample'!C35 -> One-off | C35: ='Invoice Sample'!E35 -> 6675.54 | D35: ='Invoice Sample'!M35 -> Tier 1 ($500-$10K) | E35: ='Invoice Sample'!F35 -> 2/10 Net 30 | F35: =IF(B35="Recurring",'Future-State Model'!E22,'Future-State Model'!E23) -> 1.5735294 | G35: ='Future-State Model'!E24 -> 2.4157 | H35: =IF(OR(D35="Tier 2 ($10K-$50K)",D35="Tier 3 (>$50K)"),'Future-State Model'!E25,0) -> 0 | I35: =IF(D35="Tier 3 (>$50K)",'Future-State Model'!E26,0) -> 0 | J35: ='Future-State Model'!E27 -> 0.686 | K35: =SUM(F35:J35) -> 4.6752294 | L35: =IF(E35="2/10 Net 30","Yes","No") -> Yes | M35: =IF(AND(L35="Yes",(F35+G35+H35+I35)<=10),"Yes","No") -> Yes | N35: =IF(K35>30,"Yes","No") -> No | O35: =IF(AND(L35="Yes",'Invoice Sample'!O35="No",M35="Yes"),C35*0.02,0) -> 133.5108 | P35: =IF(AND('Invoice Sample'!P35="Yes",N35="No"),C35*0.015,0) -> 0
A36: ='Invoice Sample'!A36 -> INV-2065 | B36: ='Invoice Sample'!C36 -> Recurring | C36: ='Invoice Sample'!E36 -> 6733.9 | D36: ='Invoice Sample'!M36 -> Tier 1 ($500-$10K) | E36: ='Invoice Sample'!F36 -> 2/10 Net 30 | F36: =IF(B36="Recurring",'Future-State Model'!E22,'Future-State Model'!E23) -> 0.23744186 | G36: ='Future-State Model'!E24 -> 2.4157 | H36: =IF(OR(D36="Tier 2 ($10K-$50K)",D36="Tier 3 (>$50K)"),'Future-State Model'!E25,0) -> 0 | I36: =IF(D36="Tier 3 (>$50K)",'Future-State Model'!E26,0) -> 0 | J36: ='Future-State Model'!E27 -> 0.686 | K36: =SUM(F36:J36) -> 3.3391419 | L36: =IF(E36="2/10 Net 30","Yes","No") -> Yes | M36: =IF(AND(L36="Yes",(F36+G36+H36+I36)<=10),"Yes","No") -> Yes | N36: =IF(K36>30,"Yes","No") -> No | O36: =IF(AND(L36="Yes",'Invoice Sample'!O36="No",M36="Yes"),C36*0.02,0) -> 0 | P36: =IF(AND('Invoice Sample'!P36="Yes",N36="No"),C36*0.015,0) -> 0
A37: ='Invoice Sample'!A37 -> INV-2066 | B37: ='Invoice Sample'!C37 -> One-off | C37: ='Invoice Sample'!E37 -> 8108.36 | D37: ='Invoice Sample'!M37 -> Tier 1 ($500-$10K) | E37: ='Invoice Sample'!F37 -> Net 30 | F37: =IF(B37="Recurring",'Future-State Model'!E22,'Future-State Model'!E23) -> 1.5735294 | G37: ='Future-State Model'!E24 -> 2.4157 | H37: =IF(OR(D37="Tier 2 ($10K-$50K)",D37="Tier 3 (>$50K)"),'Future-State Model'!E25,0) -> 0 | I37: =IF(D37="Tier 3 (>$50K)",'Future-State Model'!E26,0) -> 0 | J37: ='Future-State Model'!E27 -> 0.686 | K37: =SUM(F37:J37) -> 4.6752294 | L37: =IF(E37="2/10 Net 30","Yes","No") -> No | M37: =IF(AND(L37="Yes",(F37+G37+H37+I37)<=10),"Yes","No") -> No | N37: =IF(K37>30,"Yes","No") -> No | O37: =IF(AND(L37="Yes",'Invoice Sample'!O37="No",M37="Yes"),C37*0.02,0) -> 0 | P37: =IF(AND('Invoice Sample'!P37="Yes",N37="No"),C37*0.015,0) -> 0
A38: ='Invoice Sample'!A38 -> INV-2067 | B38: ='Invoice Sample'!C38 -> Recurring | C38: ='Invoice Sample'!E38 -> 145.03 | D38: ='Invoice Sample'!M38 -> Tier 0 (<$500) | E38: ='Invoice Sample'!F38 -> Net 30 | F38: =IF(B38="Recurring",'Future-State Model'!E22,'Future-State Model'!E23) -> 0.23744186 | G38: ='Future-State Model'!E24 -> 2.4157 | H38: =IF(OR(D38="Tier 2 ($10K-$50K)",D38="Tier 3 (>$50K)"),'Future-State Model'!E25,0) -> 0 | I38: =IF(D38="Tier 3 (>$50K)",'Future-State Model'!E26,0) -> 0 | J38: ='Future-State Model'!E27 -> 0.686 | K38: =SUM(F38:J38) -> 3.3391419 | L38: =IF(E38="2/10 Net 30","Yes","No") -> No | M38: =IF(AND(L38="Yes",(F38+G38+H38+I38)<=10),"Yes","No") -> No | N38: =IF(K38>30,"Yes","No") -> No | O38: =IF(AND(L38="Yes",'Invoice Sample'!O38="No",M38="Yes"),C38*0.02,0) -> 0 | P38: =IF(AND('Invoice Sample'!P38="Yes",N38="No"),C38*0.015,0) -> 0
A39: ='Invoice Sample'!A39 -> INV-2068 | B39: ='Invoice Sample'!C39 -> One-off | C39: ='Invoice Sample'!E39 -> 1017.7 | D39: ='Invoice Sample'!M39 -> Tier 1 ($500-$10K) | E39: ='Invoice Sample'!F39 -> Net 30 | F39: =IF(B39="Recurring",'Future-State Model'!E22,'Future-State Model'!E23) -> 1.5735294 | G39: ='Future-State Model'!E24 -> 2.4157 | H39: =IF(OR(D39="Tier 2 ($10K-$50K)",D39="Tier 3 (>$50K)"),'Future-State Model'!E25,0) -> 0 | I39: =IF(D39="Tier 3 (>$50K)",'Future-State Model'!E26,0) -> 0 | J39: ='Future-State Model'!E27 -> 0.686 | K39: =SUM(F39:J39) -> 4.6752294 | L39: =IF(E39="2/10 Net 30","Yes","No") -> No | M39: =IF(AND(L39="Yes",(F39+G39+H39+I39)<=10),"Yes","No") -> No | N39: =IF(K39>30,"Yes","No") -> No | O39: =IF(AND(L39="Yes",'Invoice Sample'!O39="No",M39="Yes"),C39*0.02,0) -> 0 | P39: =IF(AND('Invoice Sample'!P39="Yes",N39="No"),C39*0.015,0) -> 0
A40: ='Invoice Sample'!A40 -> INV-2069 | B40: ='Invoice Sample'!C40 -> Recurring | C40: ='Invoice Sample'!E40 -> 4855.87 | D40: ='Invoice Sample'!M40 -> Tier 1 ($500-$10K) | E40: ='Invoice Sample'!F40 -> Net 30 | F40: =IF(B40="Recurring",'Future-State Model'!E22,'Future-State Model'!E23) -> 0.23744186 | G40: ='Future-State Model'!E24 -> 2.4157 | H40: =IF(OR(D40="Tier 2 ($10K-$50K)",D40="Tier 3 (>$50K)"),'Future-State Model'!E25,0) -> 0 | I40: =IF(D40="Tier 3 (>$50K)",'Future-State Model'!E26,0) -> 0 | J40: ='Future-State Model'!E27 -> 0.686 | K40: =SUM(F40:J40) -> 3.3391419 | L40: =IF(E40="2/10 Net 30","Yes","No") -> No | M40: =IF(AND(L40="Yes",(F40+G40+H40+I40)<=10),"Yes","No") -> No | N40: =IF(K40>30,"Yes","No") -> No | O40: =IF(AND(L40="Yes",'Invoice Sample'!O40="No",M40="Yes"),C40*0.02,0) -> 0 | P40: =IF(AND('Invoice Sample'!P40="Yes",N40="No"),C40*0.015,0) -> 0
...

Sheet Summary
B2: Summary — before / after
B4: Blended cycle time (population-weighted across this sample)
B5: Current state — avg total cycle days | E5: =AVERAGE('Invoice Sample'!L2:L121) -> 12.835
B6: Future state — avg total cycle days | E6: =AVERAGE('Future-State Projection'!K2:K121) -> 4.3350973
B7: Reduction | E7: =(E5-E6)/E5 -> 0.66224407
B9: Annualized financial impact (monthly sample × 12)
B10: Months per year | F10: 12
B11: Discount $ captured / year (newly captured, future state) | E11: =SUM('Future-State Projection'!O2:O121)*F10 -> 124814.86
B12: Late fee $ avoided / year | E12: =SUM('Future-State Projection'!P2:P121)*F10 -> 0
B13: Total annual benefit | E13: =E11+E12 -> 124814.86
B15: Implementation cost
B16: Routing tool (annual) | E16: ='Future-State Model'!F16 -> 18000
B17: OCR tool (annual) | E17: ='Future-State Model'!F17 -> 9600
B18: One-time implementation (Year 1 only) | E18: ='Future-State Model'!F18 -> 22000
B19: Total Year 1 cost | E19: =E16+E17+E18 -> 49600
B21: Net benefit — Year 1 | E21: =E13-E19 -> 75214.856
B22: Net benefit — Year 2+ (subscriptions only, no re-implementation) | E22: =E13-E16-E17 -> 97214.856
